<?xml version="1.0" ?>
<!-- =================================================================================== -->
<!-- |    This document was autogenerated by xacro from diff_wheeled_robot.xacro       | -->
<!-- |    EDITING THIS FILE BY HAND IS NOT RECOMMENDED                                 | -->
<!-- =================================================================================== -->
<robot name="differential_wheeled_robot" xmlns:xacro="http://www.ros.org/wiki/xacro">
  <!-- Wheels -->
  <!-- in kg-->
  <!-- Defining the colors used in this robot -->
  <material name="Red"><color rgba="1.0 0.0 0.0 1.0" /></material>
  <material name="Green"><color rgba="0.0 1.0 0.0 1.0" /></material>
  <material name="Blue"><color rgba="0.0 0.0 1.0 1.0" /></material>
  <material name="Yellow"><color rgba="1.0 1.0 0.0 1.0" /></material>
  <material name="Cyan"><color rgba="0.0 1.0 1.0 1.0" /></material>
  <material name="Magenta"><color rgba="1.0 0.0 1.0 1.0" /></material>
  <material name="White"><color rgba="1.0 1.0 1.0 1.0" /></material>
  <material name="Black"><color rgba="0.0 0.0 0.0 1.0" /></material>
  <material name="Gray"><color rgba="0.5 0.5 0.5 1.0" /></material>
  <material name="Orange"><color rgba="1.0 0.5 0.0 1.0" /></material>
  <material name="Purple"><color rgba="0.5 0.0 0.5 1.0" /></material>
  <material name="Brown"><color rgba="0.6 0.3 0.1 1.0" /></material>
  <material name="Pink"><color rgba="1.0 0.75 0.8 1.0" /></material>
  <material name="Turquoise"><color rgba="0.25 0.88 0.82 1.0" /></material>
  <material name="Gold"><color rgba="1.0 0.84 0.0 1.0" /></material>
  <material name="Silver"><color rgba="0.75 0.75 0.75 1.0" /></material>
  <material name="black"><color rgba="0.15 0.15 0.15 1.0" /></material>
  <material name="dark_grey"><color rgba="0.2 0.2 0.2 1.0" /></material>
  <material name="light_grey"><color rgba="0.4 0.4 0.4 1.0" /></material>
  <!-- PROPERTY LIST -->
  <!--All units in m-kg-s-radians unit system -->
  <!-- Main body radius and height -->
  <!-- Main Body Cylinder base   -->
  <!-- in kg-->
  <!-- caster wheel radius and height -->
  <!-- caster wheel mass -->
  <!-- in kg-->
  <!-- caster wheel radius and height -->
  <!-- caster wheel mass -->
  <!-- in kg-->
  <!-- Wheels -->
   --&gt; 
  <!-- in kg-->
  <!-- Hokuyo Laser scanner -->
  <!-- Macro for calculating inertia of cylinder -->
  <!-- BASE-FOOTPRINT -->
  <!-- base_footprint is a fictitious link(frame) that is on the ground right below base_link origin -->
  <link name="base_footprint">
    <inertial>
      <mass value="0.0001"/>
      <origin xyz="0 0 0"/>
      <inertia ixx="0.0001" ixy="0.0" ixz="0.0" iyy="0.0001" iyz="0.0" izz="0.0001"/>
    </inertial>
    <visual>
      <origin rpy="0 0 0" xyz="0 0 0"/>
      <geometry>
        <box size="0.001 0.001 0.001"/>
      </geometry>
    </visual>
  </link>
  <gazebo reference="base_footprint">
    <turnGravityOff>false</turnGravityOff>
  </gazebo>
  <joint name="base_footprint_joint" type="fixed">
    <origin rpy="0 0 0" xyz="0 0 0.04"/>
    <parent link="base_footprint"/>
    <child link="base_link"/>
  </joint>
  <!-- BASE-LINK -->
  <!--Actual body/chassis of the robot-->
  <link name="base_link">
    <inertial>
      <mass value="5"/>
      <origin xyz="0 0 0"/>
      <!--The 3x3 rotational inertia matrix. -->
      <inertia ixx="0.0282916666667" ixy="0" ixz="0" iyy="0.0282916666667" iyz="0" izz="0.05625"/>
    </inertial>
    <visual>
      <origin rpy="0 0 0" xyz="0 0 0"/>
      <geometry>
        <cylinder length="0.02" radius="0.15"/>
      </geometry>
      <material name="White"/>
    </visual>
    <collision>
      <origin rpy="0 0 0 " xyz="0 0 0"/>
      <geometry>
        <cylinder length="0.02" radius="0.15"/>
      </geometry>
    </collision>
  </link>
  <gazebo reference="base_link">
    <material>Gazebo/White</material>
    <turnGravityOff>false</turnGravityOff>
  </gazebo>
  <!--fb : front, back ; lr: left, right -->
  <link name="front_right_wheel">
    <visual>
      <origin rpy="1.57079632679 0  0 " xyz="0 0 0"/>
      <geometry>
        <cylinder length="0.02" radius="0.04"/>
      </geometry>
      <material name="DarkGray"/>
    </visual>
    <collision>
      <origin rpy="1.57079632679 0 0 " xyz="0 0 0"/>
      <geometry>
        <cylinder length="0.02" radius="0.04"/>
      </geometry>
    </collision>
    <inertial>
      <mass value="2.5"/>
      <origin xyz="0 0 0"/>
      <inertia ixx="0.00108333333333" ixy="0" ixz="0" iyy="0.00108333333333" iyz="0" izz="0.002"/>
    </inertial>
  </link>
  <gazebo reference="front_right_wheel">
    <mu1 value="0.01"/>
    <mu2 value="0.01"/>
    <kp value="10000000.0"/>
    <kd value="1.0"/>
    <fdir1 value="1 0 0"/>
    <material>Gazebo/Grey</material>
    <turnGravityOff>false</turnGravityOff>
  </gazebo>
  <joint name="front_right_wheel_joint" type="continuous">
    <parent link="base_link"/>
    <child link="front_right_wheel"/>
    <origin rpy="0 0 0" xyz="0.0 0.15 0.0"/>
    <axis rpy="0  0" xyz="0 1 0"/>
    <limit effort="100" velocity="100"/>
    <joint_properties damping="0.0" friction="0.0"/>
  </joint>
  <!-- Transmission is important to link the joints and the controller -->
  <transmission name="front_right_wheel_joint_trans">
    <type>transmission_interface/SimpleTransmission</type>
    <joint name="front_right_wheel_joint"/>
    <actuator name="front_right_wheel_joint_motor">
      <hardwareInterface>EffortJointInterface</hardwareInterface>
      <mechanicalReduction>1</mechanicalReduction>
    </actuator>
  </transmission>
  <!--fb : front, back ; lr: left, right -->
  <link name="front_left_wheel">
    <visual>
      <origin rpy="1.57079632679 0  0 " xyz="0 0 0"/>
      <geometry>
        <cylinder length="0.02" radius="0.04"/>
      </geometry>
      <material name="DarkGray"/>
    </visual>
    <collision>
      <origin rpy="1.57079632679 0 0 " xyz="0 0 0"/>
      <geometry>
        <cylinder length="0.02" radius="0.04"/>
      </geometry>
    </collision>
    <inertial>
      <mass value="2.5"/>
      <origin xyz="0 0 0"/>
      <inertia ixx="0.00108333333333" ixy="0" ixz="0" iyy="0.00108333333333" iyz="0" izz="0.002"/>
    </inertial>
  </link>
  <gazebo reference="front_left_wheel">
    <mu1 value="0.01"/>
    <mu2 value="0.01"/>
    <kp value="10000000.0"/>
    <kd value="1.0"/>
    <fdir1 value="1 0 0"/>
    <material>Gazebo/Grey</material>
    <turnGravityOff>false</turnGravityOff>
  </gazebo>
  <joint name="front_left_wheel_joint" type="continuous">
    <parent link="base_link"/>
    <child link="front_left_wheel"/>
    <origin rpy="0 0 0" xyz="0.0 -0.15 0.0"/>
    <axis rpy="0  0" xyz="0 1 0"/>
    <limit effort="100" velocity="100"/>
    <joint_properties damping="0.0" friction="0.0"/>
  </joint>
  <!-- Transmission is important to link the joints and the controller -->
  <transmission name="front_left_wheel_joint_trans">
    <type>transmission_interface/SimpleTransmission</type>
    <joint name="front_left_wheel_joint"/>
    <actuator name="front_left_wheel_joint_motor">
      <hardwareInterface>EffortJointInterface</hardwareInterface>
      <mechanicalReduction>1</mechanicalReduction>
    </actuator>
  </transmission>
  <!--Caster front  -->
  <link name="caster_front_link">
    <visual>
      <origin rpy="1.57079632679 0 0" xyz="0 0.02 0"/>
      <geometry>
        <sphere radius="0.025"/>
      </geometry>
      <material name="Black"/>
    </visual>
    <collision>
      <geometry>
        <sphere radius="0.025"/>
      </geometry>
      <origin rpy="1.57079632679 0 0" xyz="0 0.02 0"/>
    </collision>
    <inertial>
      <mass value="0.5"/>
      <origin xyz="0 0 0"/>
      <inertia ixx="0.001" ixy="0.0" ixz="0.0" iyy="0.001" iyz="0.0" izz="0.001"/>
    </inertial>
  </link>
  <joint name="caster_front_joint" type="fixed">
    <parent link="base_link"/>
    <child link="caster_front_link"/>
    <origin rpy="-1.57079632679 0 0" xyz="0.115 0.0 0.007"/>
  </joint>
  <gazebo reference="caster_front_link">
    <turnGravityOff>false</turnGravityOff>
  </gazebo>
  <!--Caster back  -->
  <link name="caster_back_link">
    <visual>
      <origin rpy="1.57079632679 0 0" xyz="0.02 0.02 0 "/>
      <geometry>
        <sphere radius="0.025"/>
      </geometry>
      <material name="Black"/>
    </visual>
    <collision>
      <geometry>
        <sphere radius="0.025"/>
      </geometry>
      <origin rpy="1.57079632679 0 0" xyz="0 0.02 0 "/>
    </collision>
    <inertial>
      <mass value="0.5"/>
      <origin xyz="0 0 0"/>
      <inertia ixx="0.001" ixy="0.0" ixz="0.0" iyy="0.001" iyz="0.0" izz="0.001"/>
    </inertial>
  </link>
  <joint name="caster_back_joint" type="fixed">
    <parent link="base_link"/>
    <child link="caster_back_link"/>
    <origin rpy="-1.57079632679 0 0" xyz="-0.135 0.0 0.009"/>
  </joint>
  <gazebo reference="caster_back_link">
    <turnGravityOff>false</turnGravityOff>
  </gazebo>
  <!-- SENSORS -->
  <!-- hokuyo -->
  <link name="hokuyo_link">
    <visual>
      <origin rpy="0 0 0" xyz="0 0 0"/>
      <geometry>
        <box size="0.05 0.05 0.05"/>
      </geometry>
      <material name="Blue"/>
    </visual>
  </link>
  <joint name="hokuyo_joint" type="fixed">
    <origin rpy="0 0 0" xyz="0.125 0 0.0325"/>
    <parent link="base_link"/>
    <child link="hokuyo_link"/>
  </joint>
      <gazebo>
    <!-- <plugin name="gazebo_ros_control" filename="libgazebo_ros_control.so">
      <robotNamespace>/</robotNamespace>
    </plugin> -->

    <plugin name="nexus_ros_force_based_move" filename="libnexus_ros_force_based_move.so">
      <commandTopic>cmd_vel</commandTopic>
      <odometryTopic>odom</odometryTopic>
      <odometryFrame>odom</odometryFrame>
      <odometryRate>25.0</odometryRate>
      <robotBaseFrame>base_footprint</robotBaseFrame>
      <cmdVelTimeOut>0.25</cmdVelTimeOut>
      <publishOdometryTf>1</publishOdometryTf>
      <yaw_velocity_p_gain>1.0</yaw_velocity_p_gain>
      <x_velocity_p_gain>15.0</x_velocity_p_gain>
      <y_velocity_p_gain>15.0</y_velocity_p_gain>
      <max_x_velocity>0.6</max_x_velocity>
      <max_y_velocity>0.6</max_y_velocity>
      <max_yaw_velocity>0.5</max_yaw_velocity>
    </plugin>
  </gazebo>
  <!--
	  <gazebo>
	    <plugin name="kobuki_controller" filename="libgazebo_ros_kobuki.so">
	      <publish_tf>1</publish_tf>
	      <left_wheel_joint_name>front_left_wheel_joint</left_wheel_joint_name>
	      <right_wheel_joint_name>front_right_wheel_joint</right_wheel_joint_name>
	      <wheel_separation>.30</wheel_separation>
	      <wheel_diameter>0.08</wheel_diameter>
	      <torque>30.0</torque>
	      <velocity_command_timeout>0.6</velocity_command_timeout>
	    </plugin>
	  </gazebo>
-->
  <!--
<gazebo>
    <plugin name="gazebo_ros_control" filename="libgazebo_ros_control.so" />
    <plugin filename="libgazebo_ros_joint_state_publisher.so" name="joint_state_publisher">
      <jointName>front_right_wheel_joint, front_left_wheel_joint</jointName>
      <updateRate>10.0</updateRate>
      <alwaysOn>true</alwaysOn>
    </plugin>
</gazebo>
-->
</robot>
